Workbook

Sheet Instructions
A1: SE Lab Assignment 1 Team Workbook
A2: Smart Ticketing System (TVM) | Sem 1_2627 | One workbook per group, kept in your shared folder and in your GitHub repository
A4: Purpose
A5: This workbook is your group's working record for Lab Group Assignment 1. It contains the Clarification Q&A and the requirements (two deliverables you hand in as Excel or Word), plus trackers that show your process: who built what, the diagrams and their status, your Copilot prompts, your commits and your weekly progress. The lecturer reads it during the labs and replies in the green cells. Student self-marking and lecturer marking are on the Marking sheet. It supports, and does not replace, your official submission (the .docx report, readme.txt and the % contribution).
A7: How to use it
A8: 1. Fill in the Team sheet first (3 to 5 students, % contribution totalling 100%).
A9: 2. Do the Clarification Q&A before you write the requirements. Every assumed answer should lead to a requirement ID.
A10: 3. Update the Artifact Tracker, Commit Log, AI Prompt Log and Progress Log every lab week. These show the process mark evidence.
A11: 4. Before submission, use the Consistency Check sheet, then self-mark on the Marking sheet. The lecturer marks in the green column.
A13: Colour legend
A14: Student input | B14: Yellow fill, blue text
A15: Lecturer input | B15: Green fill, blue text
A16: Calculated / fixed | B16: Black text, no fill
A18: Sheets in this workbook
A19: Sheet | B19: What it is for | C19: Report section it feeds | D19: When to fill in
A20: Team | B20: Members, roles, % contribution, commit counts | C20: 1.3, 7 | D20: Week 1
A21: Clarification Q&A | B21: Ambiguities, questions and assumed answers (Task 1, 5%) | C21: 2.1 | D21: Before requirements
A22: Requirements | B22: Functional, non-functional and domain requirements with measurable metrics (Task 2, 15%) | C22: 2.2 | D22: Phase 1
A23: Use Cases | B23: Use case register and description status (Task 3) | C23: 3.1 | D23: Phase 2
A24: Artifact Tracker | B24: Every deliverable: owner, tool, link, status, % done | C24: All | D24: Throughout
A25: Consistency Check | B25: Alignment of the diagrams and the code | C25: 3.4 | D25: Before submitting
A26: AI Prompt Log | B26: Copilot prompts, how the AI helped, how you validated (Task 9) | C26: 5.2.2 | D26: Throughout
A27: Commit Log | B27: Commits and pull requests per member per week | C27: 5.2.1 | D27: Weekly
A28: Progress Log | B28: Weekly plan, actual work, evidence and lecturer feedback | C28: Process mark | D28: Weekly
A29: Marking | B29: Self-mark and lecturer mark for the 10 tasks (100%) | C29: – | D29: End
A30: Summary | B30: Group result, QT2 points and individual marks | C30: – | D30: End

Sheet Team
A1: Team and Contribution
A2: Group of 3 to 5 students. The % contribution of each member must total 100% and match your readme.txt.
A4: Group name | B4: Group 69
A5: GitHub repo | B5: https://github.com/Narwhal1412/SE-QT2
A6: Group size | B6: =COUNTA(C11:C15) -> 3
A7: Size check | B7: =IF(AND(B6>=3,B6<=5),"OK","Group must have 3 to 5 students") -> OK
A9: Members
A10: Member | B10: Name | C10: Student ID | D10: Role / main responsibility | E10: % contribution | F10: Commits (from Commit Log) | G10: Check
A11: Member 1 | B11: Trần Đỗ Quốc Anh | C11: 524H0041 | D11: Requirements Engineering (Q&A, FR/NFR/DR), Use Case Modeling & Descriptions, State Chart Diagram, Test Scenarios | E11: 0.3 | F11: =IF(C11="","",SUMIF('Commit Log'!$C$5:$C$64,C11,'Commit Log'!$E$5:$E$64)) -> 0 | G11: =IF(C11="","",IF(AND(ISNUMBER(F11),F11>0),"OK","No commits yet")) -> No commits yet
A12: Member 2 | B12: Nguyễn Gia Huy | C12: 524H0158 | D12: Team Lead, System Architecture (MVC & Deployment), Domain Model, C# .NET 10 WinForms Implementation, MSSQL Database & Repository | E12: 0.4 | F12: =IF(C12="","",SUMIF('Commit Log'!$C$5:$C$64,C12,'Commit Log'!$E$5:$E$64)) -> 0 | G12: =IF(C12="","",IF(AND(ISNUMBER(F12),F12>0),"OK","No commits yet")) -> No commits yet
A13: Member 3 | B13: Lê Anh Tuân | C13: 524H0074 | D13: UML Activity Diagrams, Sequence Diagram, Payment Adapters, Visual Studio Model-to-Code Engineering & Code Map, Copilot Prompt Validation | E13: 0.3 | F13: =IF(C13="","",SUMIF('Commit Log'!$C$5:$C$64,C13,'Commit Log'!$E$5:$E$64)) -> 0 | G13: =IF(C13="","",IF(AND(ISNUMBER(F13),F13>0),"OK","No commits yet")) -> No commits yet
A14: Member 4 | F14: =IF(C14="","",SUMIF('Commit Log'!$C$5:$C$64,C14,'Commit Log'!$E$5:$E$64)) | G14: =IF(C14="","",IF(AND(ISNUMBER(F14),F14>0),"OK","No commits yet"))
A15: Member 5 | F15: =IF(C15="","",SUMIF('Commit Log'!$C$5:$C$64,C15,'Commit Log'!$E$5:$E$64)) | G15: =IF(C15="","",IF(AND(ISNUMBER(F15),F15>0),"OK","No commits yet"))
D16: Total contribution | E16: =SUM(E11:E15) -> 1
D17: Check | E17: =IF(ROUND(E16,4)=1,"OK","Must total 100%") -> OK
A19: Contribution is the share of the whole project each member built, in agreement with the group. The lecturer may adjust it using the Git history, the pull requests and individual questions.

Sheet Clarification Q&A
A1: Clarification Q&A (Task 1, 5 marks)
A2: Identify the ambiguities in the problem statement, ask the stakeholders, and give logical assumed answers to base your design on.
A4: Q ID | B4: Area | C4: Ambiguity found in the problem statement | D4: Clarifying question to the stakeholder | E4: Stakeholder asked | F4: Assumed answer (logical) | G4: Rationale and impact on the design | H4: Requirement ID | I4: Status | J4: Lecturer comment
A5: Q01 | B5: Ticket and fares | C5: The statement does not say which ticket types, modes or origins one TVM sells. | D5: Which ticket types and transport modes does one TVM sell, and can it sell tickets for any origin? | E5: Transport authority | F5: The TVM sells single-journey tickets and 1-day passes for MRT and bus. The origin is always the station or stop where the TVM is installed; the passenger chooses only the destination. | G5: Fixes the scope of the destination menu and removes the need for an origin selection screen. | H5: FR2, FR3 | I5: Final
A6: Q02 | B6: Ticket and fares | C6: The statement does not say how the fare is calculated, in which currency or with what rounding. | D6: How is the fare calculated, and in which currency and rounding? | E6: Transport authority | F6: Fare comes from a fare table by origin and destination (zone / distance based), in whole VND rounded to the nearest 1,000 VND. The table is maintained centrally. | G6: The fare must be shown before payment and must be identical on screen, payment request and ticket. | H6: FR4, DR1, DR2 | I6: Final
A7: Q03 | B7: Ticket and fares | C7: The statement does not mention passenger categories or buying several tickets at once. | D7: Are there passenger categories (student, senior) and can one transaction buy several tickets? | E7: Transport authority | F7: Fare categories are Adult, Student and Senior. One transaction can buy 1 to 5 tickets of the same type and destination. | G7: Affects the selection screens, the total fare and the number of barcodes printed. | H7: FR3, DR2 | I7: Final
A8: Q04 | B8: Ticket and fares | C8: The statement does not say what the ticket shows, which barcode is used or how long it is valid. | D8: What must be printed on the ticket, which barcode type is used, and how long is the ticket valid? | E8: Operator | F8: Ticket shows ticket number, origin, destination, type, fare, date-time, expiry and TVM ID. Barcode is Code 128. A single-journey ticket is valid for one entry within 60 minutes on the day of issue. | G8: Gates must be able to validate the ticket. The validity rule defines what happens to tickets that are not used. | H8: FR10, DR3, DR4 | I8: Final
A9: Q05 | B9: Payment | C9: The statement lists three payment modes but not on which screen or in which order they are chosen. | D9: On which screen and in which order does the passenger select the payment mode? | E9: Operator | F9: After the fare summary the TVM shows a payment-mode screen with three buttons (Credit Card, Bank QR, Digital Wallet); unavailable modes are hidden. | G9: Defines the main flow order: Start, destination, fare, payment mode, payment, ticket. | H9: FR1, FR5 | I9: Final
A10: Q06 | B10: Payment | C10: The statement says 'credit card' but not which cards, entry methods or when a PIN is needed. | D10: Which cards and entry methods are accepted, and when is a PIN needed? | E10: Bank / payment gateway | F10: Visa, Mastercard, JCB and NAPAS credit and debit cards, by insert or tap. PIN is requested on a PIN pad when the processor asks for it (for example above the contactless limit). | G10: Defines the card reader hardware, the PIN pad and the PCI scope. | H10: FR6, DR5 | I10: Final
A11: Q07 | B11: Integration | C11: Bank QR and wallet QR are both mentioned but their difference and how payment is confirmed are unclear. | D11: Are bank QR and wallet QR different payment methods, and how does the TVM learn that either was paid? | E11: Bank / payment gateway | F11: Both are dynamic QR codes shown on the TVM. Bank QR follows VietQR and the bank notifies the server; the wallet QR is provider specific and the wallet notifies the server by callback. The TVM never reads the passenger's phone. | G11: Two separate integrations with different confirmation messages; both must be modelled in the activity and sequence diagrams. | H11: FR7, FR8, DR6, DR7 | I11: Final
A12: Q08 | B12: Integration | C12: The statement does not name the wallet gateways or say whether more can be added later. | D12: Which wallet gateways must be supported at launch, and must more be added later? | E12: Bank / payment gateway | F12: Momo, ZaloPay and VNPay at launch. The passenger chooses the wallet on screen. The payment service uses one common interface so a new gateway can be added without changing the TVM. | G12: Leads to a payment-service layer and an adapter per gateway in the architecture and class diagram. | H12: FR8, DR7 | I12: Final
A13: Q09 | B13: Payment | C13: It is unclear whether the card is authorised first and captured later or charged at once. | D13: Is the card authorised first and captured later, or charged at once? | E13: Bank / payment gateway | F13: The card is authorised and captured in one step when the issuer approves. If the ticket cannot be printed, the payment is voided or refunded automatically. | G13: Decides when the ticket may be printed and what must be reversed after a print failure. | H13: FR9, FR15 | I13: Final
A14: Q10 | B14: Failure handling | C14: The statement does not say what happens when a card is declined. | D14: What happens if the card is declined, and how many attempts are allowed? | E14: Bank / payment gateway | F14: A clear message is shown. The passenger has up to 3 attempts in total (same or other card) or can change payment mode; then the transaction is cancelled. | G14: Adds a loop and failure paths to the activity diagram and a retry counter to the model. | H14: FR14 | I14: Final
A15: Q11 | B15: Failure handling | C15: No waiting times are defined, so the TVM could wait for ever at any step. | D15: How long does the TVM wait at each step before giving up? | E15: Operator | F15: Idle on a selection screen: 60 s. Card prompt: 30 s. QR payment: 120 s. After a timeout the TVM offers "Try again" or "Cancel". | G15: Timeouts create states and transitions in the state chart and exception flows in the use cases. | H15: FR12, FR13 | I15: Final
A16: Q12 | B16: Failure handling | C16: It is unclear what happens when a payment is confirmed after the transaction timed out or was cancelled. | D16: What should happen to a payment that is confirmed after the transaction timed out or was cancelled? | E16: Bank / payment gateway | F16: No ticket is printed. The late payment is automatically refunded, and every payment request has a unique transaction ID so the same payment can never be applied twice. | G16: Hidden complexity: asynchronous callbacks and duplicate prevention drive the sequence diagram and the data model. | H16: FR16, NFR2 | I16: Final
... A29: Q25 | B29: Other | C29: Record keeping, checking and retention of transactions are not described. | D29: Which records must be kept, how are they checked, and for how long? | E29: Transport authority | F29: Every transaction step is logged and synchronised; each day the back-office reconciles with provider settlement files. Records are kept for 5 years (to be confirmed by Finance and Legal) and handled under Decree 13/2023/ND-CP. | G29: Adds the reconciliation use case and the retention and privacy rule. | H29: FR17, FR22, DR8 | I29: Final
C31: Questions written | D31: =COUNTA(D5:D29) -> 25
C32: Questions linked to a requirement | D32: =COUNTA(H5:H29) -> 25
C33: Areas covered | D33: =SUMPRODUCT((B5:B29<>"")/COUNTIF(B5:B29,B5:B29&"")) -> 9
A35: Strong Q&A uncovers hidden complexity (timeouts, declined payments, refunds, printer or paper out, offline mode, fares). Aim for several different areas, not many questions on one topic.

Sheet Requirements
A1: Requirements Specification (Task 2, 15 marks)
A2: Functional, Non-Functional and Domain requirements. Every NFR needs a measurable metric. Focus: reliability and response time.
A4: ID | B4: Requirement | C4: Type | D4: Category (NFR) | E4: Measurable metric / fit criterion (NFR) | F4: Measurement method | G4: Priority | H4: Use case | I4: Source (Q ID) | J4: Lecturer comment
A5: =IF(C5="","",C5&COUNTIF($C$5:C5,C5)) -> FR1 | B5: The TVM shall display a welcome screen with a "Start" button and a language selector (Vietnamese / English) whenever it is idle. | C5: FR | G5: High | H5: UC01 | I5: Q05, Q23
A6: =IF(C6="","",C6&COUNTIF($C$5:C6,C6)) -> FR2 | B6: After the passenger presses "Start", the TVM shall display a menu of destinations (stations and bus stops), grouped by line / mode (MRT, Bus) and searchable by name. | C6: FR | G6: High | H6: UC02 | I6: Q01
A7: =IF(C7="","",C7&COUNTIF($C$5:C7,C7)) -> FR3 | B7: The TVM shall let the passenger choose the ticket type (single journey or 1-day pass), the fare category (Adult, Student, Senior) and the quantity (1 to 5 tickets per transaction). | C7: FR | G7: Medium | H7: UC02 | I7: Q01, Q03
A8: =IF(C8="","",C8&COUNTIF($C$5:C8,C8)) -> FR4 | B8: The TVM shall calculate the total fare in VND from the current fare table (origin = this TVM's station, destination = selected) and show it to the passenger before payment is requested. | C8: FR | G8: High | H8: UC02 | I8: Q02
A9: =IF(C9="","",C9&COUNTIF($C$5:C9,C9)) -> FR5 | B9: The TVM shall present a payment-mode screen offering Credit Card, Bank QR Code and Digital Wallet, and shall show only the modes that are currently available. | C9: FR | G9: High | H9: UC01 | I9: Q05
A10: =IF(C10="","",C10&COUNTIF($C$5:C10,C10)) -> FR6 | B10: For card payment, the TVM shall prompt the passenger to insert or tap a credit / debit card, request authorisation from the card processor, and ask for a PIN on the secure PIN pad when the processor requires it. | C10: FR | G10: High | H10: UC03 | I10: Q06, Q16
A11: =IF(C11="","",C11&COUNTIF($C$5:C11,C11)) -> FR7 | B11: For Bank QR payment, the TVM shall generate a dynamic bank QR code (amount and transaction reference embedded), display it on screen and wait for the bank's payment confirmation. | C11: FR | G11: High | H11: UC04 | I11: Q07
A12: =IF(C12="","",C12&COUNTIF($C$5:C12,C12)) -> FR8 | B12: For Digital Wallet payment, the TVM shall let the passenger pick a wallet (Momo, ZaloPay or VNPay), generate and display that wallet's QR code, and wait for the wallet gateway's payment confirmation. | C12: FR | G12: High | H12: UC05 | I12: Q07, Q08
A13: =IF(C13="","",C13&COUNTIF($C$5:C13,C13)) -> FR9 | B13: The TVM shall issue a ticket only after the payment processor has returned a confirmed (approved / paid) status for the transaction. | C13: FR | G13: High | H13: UC01, UC06 | I13: Q09
A14: =IF(C14="","",C14&COUNTIF($C$5:C14,C14)) -> FR10 | B14: The TVM shall print a paper ticket carrying a barcode, ticket number, origin, destination, ticket type, fare, issue date-time, expiry and TVM ID, and then show a success screen with the transaction reference. | C14: FR | G14: High | H14: UC06 | I14: Q04
A15: =IF(C15="","",C15&COUNTIF($C$5:C15,C15)) -> FR11 | B15: The TVM shall provide a "Cancel" button on every screen before payment is confirmed; cancelling shall void any pending payment session (including displayed QR codes) and return the TVM to Idle. | C15: FR | G15: High | H15: UC07 | I15: Q13
A16: =IF(C16="","",C16&COUNTIF($C$5:C16,C16)) -> FR12 | B16: The TVM shall discard the current selection and return to the welcome screen after 60 seconds without passenger input before a payment has been started. | C16: FR | G16: Medium | H16: UC01 | I16: Q11
... A26: =IF(C26="","",C26&COUNTIF($C$5:C26,C26)) -> FR22 | B26: The back-office shall reconcile TVM transactions with the settlement files of the card processor, bank and wallet gateways once per day and flag every mismatch for review. | C26: FR | G26: Medium | H26: UC12 | I26: Q25
A27: =IF(C27="","",C27&COUNTIF($C$5:C27,C27)) -> NFR1 | B27: At least 99.5% of transactions with confirmed payment shall end with a readable ticket printed without staff intervention; all others shall end in an automatic refund (see the refund requirement). | C27: NFR | D27: Reliability | E27: ≥ 99.5% of paid transactions print a ticket without staff help | F27: Monthly analysis of transaction log (paid vs. printed) and printer error log | G27: High | H27: UC06, UC08 | I27: Q14, Q18
A28: =IF(C28="","",C28&COUNTIF($C$5:C28,C28)) -> NFR2 | B28: No customer shall be charged without receiving a ticket or a refund: 100% of confirmed payments shall end as a printed ticket or an initiated refund, and the refund request shall be submitted within 60 seconds of the failure in 99% of cases. | C28: NFR | D28: Reliability | E28: 100% of confirmed payments end in a ticket or a refund; refund submitted ≤ 60 s in 99% of cases | F28: Daily reconciliation report; fault-injection test (paper out, jam, power cut) repeated 100 times | G28: High | H28: UC08 | I28: Q12, Q14
A29: =IF(C29="","",C29&COUNTIF($C$5:C29,C29)) -> NFR3 | B29: After a power loss or software crash the TVM shall restart to the Idle screen within 90 seconds and shall recover any in-flight transaction from local storage without a duplicate charge. | C29: NFR | D29: Reliability | E29: Restart to Idle ≤ 90 s after power loss; no duplicate charge | F29: Forced power-cut test on a test TVM (50 repetitions) with log inspection | G29: High | H29: UC01, UC08, UC12 | I29: Q20
A30: =IF(C30="","",C30&COUNTIF($C$5:C30,C30)) -> NFR4 | B30: When the central server or payment network cannot be reached, the TVM shall detect it within 10 seconds, disable the card, QR and wallet options, and keep up to 10,000 log records locally to synchronise within 5 minutes after the connection returns. | C30: NFR | D30: Reliability | E30: Network loss detected ≤ 10 s; 10,000 records buffered; sync ≤ 5 min after reconnection | F30: Network-cut test (disconnect, wait, reconnect) with timestamps from the TVM log | G30: High | H30: UC01, UC10, UC12 | I30: Q20
A31: =IF(C31="","",C31&COUNTIF($C$5:C31,C31)) -> NFR5 | B31: Each TVM shall be available for sale for at least 99.5% of its operating hours (05:00 to 23:00 daily) in every calendar month, excluding planned maintenance. | C31: NFR | D31: Availability | E31: TVM availability ≥ 99.5% of operating hours (05:00-23:00) | F31: Heartbeat records from the monitoring server (up time / scheduled time) | G31: High | H31: UC10 | I31: Q18
A32: =IF(C32="","",C32&COUNTIF($C$5:C32,C32)) -> NFR6 | B32: The central ticketing server (payment service, database, back-office) shall be available at least 99.9% of the time in every calendar month. | C32: NFR | D32: Availability | E32: Server availability ≥ 99.9% per month | F32: Uptime monitoring probe every 30 s on the payment-service endpoint | G32: High | H32: UC01, UC10, UC12 | I32: Q18
A33: =IF(C33="","",C33&COUNTIF($C$5:C33,C33)) -> NFR7 | B33: The TVM shall display the destination menu within 1.0 second of the Start button being pressed in 95% of cases, and within 2.0 seconds in 99% of cases. | C33: NFR | D33: Response time | E33: Destination menu ≤ 1.0 s (95%) and ≤ 2.0 s (99%) | F33: Timestamps in the TVM log over 1,000 transactions | G33: High | H33: UC02 | I33: Q17
A34: =IF(C34="","",C34&COUNTIF($C$5:C34,C34)) -> NFR8 | B34: The TVM shall give visible feedback to every touch within 200 milliseconds in 99% of touches. | C34: NFR | D34: Response time | E34: Touch feedback ≤ 200 ms in 99% of touches | F34: High-speed camera / UI event timestamps over 500 touches | G34: Medium | H34: UC01, UC02 | I34: Q17
A35: =IF(C35="","",C35&COUNTIF($C$5:C35,C35)) -> NFR9 | B35: After a destination is selected, the TVM shall display the fare summary and payment-mode screen within 1.0 second in 95% of cases. | C35: NFR | D35: Response time | E35: Fare and payment-mode screen ≤ 1.0 s in 95% of cases | F35: Timestamps in the TVM log over 1,000 transactions | G35: High | H35: UC01, UC02 | I35: Q17
A36: =IF(C36="","",C36&COUNTIF($C$5:C36,C36)) -> NFR10 | B36: The TVM shall show the card result (approved or declined) within 5 seconds of the card being tapped or inserted in 95% of cases, and shall treat no answer within 10 seconds as a timeout. | C36: NFR | D36: Response time | E36: Card result ≤ 5 s in 95% of cases; timeout at 10 s | F36: Timestamps (card read, authorisation response) over 1,000 card payments in the test environment | G36: High | H36: UC03 | I36: Q17
A37: =IF(C37="","",C37&COUNTIF($C$5:C37,C37)) -> NFR11 | B37: The TVM shall display the QR code within 2.0 seconds of the passenger selecting Bank QR or a wallet in 95% of cases, and within 4.0 seconds in 99% of cases. | C37: NFR | D37: Response time | E37: QR code shown ≤ 2.0 s (95%) and ≤ 4.0 s (99%) | F37: Timestamps (selection, QR rendered) over 1,000 QR requests against the gateway sandbox | G37: High | H37: UC04, UC05 | I37: Q17
A38: =IF(C38="","",C38&COUNTIF($C$5:C38,C38)) -> NFR12 | B38: After the server receives a payment confirmation from a gateway, the TVM shall show "Payment received" within 2 seconds in 95% of cases. | C38: NFR | D38: Response time | E38: 'Payment received' shown ≤ 2 s in 95% of cases | F38: Server and TVM timestamps over 1,000 sandbox payments | G38: High | H38: UC01, UC04, UC05, UC06 | I38: Q17
... A46: =IF(C46="","",C46&COUNTIF($C$5:C46,C46)) -> NFR20 | B46: The central system shall support 500 TVMs and a peak of 100 transactions per second while keeping all response-time requirements above. | C46: NFR | D46: Capacity | E46: 500 TVMs and 100 transactions/s at peak with response times kept | F46: Load test (JMeter or similar) for 30 minutes at peak load | G46: Medium | H46: UC01, UC06, UC12 | I46: Q19
A47: =IF(C47="","",C47&COUNTIF($C$5:C47,C47)) -> DR1 | B47: All fares shall be in Vietnamese dong (VND) as whole numbers, rounded to the nearest 1,000 VND, with the same fare shown on screen, ticket and payment request. (Related: FR4, FR10) | C47: DR | F47: Source: Transport authority fare policy; VND | G47: High | H47: UC02, UC06 | I47: Q02
A48: =IF(C48="","",C48&COUNTIF($C$5:C48,C48)) -> DR2 | B48: The fare shall be taken from the transport authority's fare table by origin and destination (zone or distance based), with a discount for Student and Senior categories and a lower price for the 1-day pass, as defined by the authority. (Related: FR4, FR3) | C48: DR | F48: Source: Transport authority fare policy | G48: High | H48: UC02 | I48: Q02, Q03
A49: =IF(C49="","",C49&COUNTIF($C$5:C49,C49)) -> DR3 | B49: A single-journey ticket shall be valid for one entry within 60 minutes of issue on the day of issue; a 1-day pass shall be valid for unlimited entry until the end of service on the day of issue. (Related: FR10) | C49: DR | F49: Source: Operator ticketing rules | G49: High | H49: UC06 | I49: Q04
A50: =IF(C50="","",C50&COUNTIF($C$5:C50,C50)) -> DR4 | B50: The barcode shall be Code 128 encoding a unique, non-sequential ticket number plus a verification code, so that gates can validate the ticket against the central database or by signature when offline. (Related: FR10) | C50: DR | F50: Source: Operator gate system; Code 128 (ISO/IEC 15417) | G50: High | H50: UC06 | I50: Q04
A51: =IF(C51="","",C51&COUNTIF($C$5:C51,C51)) -> DR5 | B51: Card acceptance shall follow EMV contact and contactless rules, and the TVM and its payment flow shall comply with PCI DSS and PCI PTS for the PIN pad. (Related: FR6, NFR15) | C51: DR | F51: Source: EMVCo; PCI SSC (PCI DSS, PCI PTS) | G51: High | H51: UC03, UC08 | I51: Q06, Q21
A52: =IF(C52="","",C52&COUNTIF($C$5:C52,C52)) -> DR6 | B52: Bank QR codes shall follow the VietQR (NAPAS) standard so that any participating banking app can pay them. (Related: FR7) | C52: DR | F52: Source: NAPAS VietQR standard | G52: High | H52: UC04 | I52: Q07
A53: =IF(C53="","",C53&COUNTIF($C$5:C53,C53)) -> DR7 | B53: Wallet payments shall follow each provider's merchant API contract (Momo, ZaloPay, VNPay): signed requests, server-to-server confirmation (callback / IPN), and daily settlement files. (Related: FR8, NFR16) | C53: DR | F53: Source: Momo, ZaloPay and VNPay merchant API contracts | G53: High | H53: UC05, UC08 | I53: Q07, Q08
A54: =IF(C54="","",C54&COUNTIF($C$5:C54,C54)) -> DR8 | B54: Personal and transaction data shall be handled according to Vietnamese personal-data protection rules (Decree 13/2023/ND-CP), and transaction and audit records shall be kept for 5 years (period to be confirmed by the operator's Finance and Legal teams). (Related: FR17, FR22) | C54: DR | F54: Source: Decree 13/2023/ND-CP; accounting record rules (to be confirmed) | G54: Medium | H54: UC01, UC12 | I54: Q25
B56: Functional requirements | C56: =COUNTIF(C5:C54,"FR") -> 22
B57: Non-functional requirements | C57: =COUNTIF(C5:C54,"NFR") -> 20
B58: Domain requirements | C58: =COUNTIF(C5:C54,"DR") -> 8
...

Sheet Use Cases
A1: Use Case Register (Task 3)
A2: One row per use case. Each needs a full description and appears in the use case diagram.
A4: ID | B4: Use case | C4: Primary actor | D4: Short description | E4: Requirement IDs | F4: Description written? | G4: In activity / sequence diagram? | H4: Owner (ID) | I4: Lecturer comment
A5: UC01 | B5: Buy a Ticket | C5: Passenger | D5: Main use case: from pressing Start to receiving the ticket. Includes UC02, one of UC03/UC04/UC05 for payment, and UC06. | E5: FR1, FR5, FR9, FR12, FR17 | F5: Yes | H5: 524H0041
A6: UC02 | B6: Select Destination and Ticket Options | C6: Passenger | D6: Choose destination, ticket type, fare category and quantity and see the fare. | E6: FR2, FR3, FR4 | F6: Yes | H6: 524H0041
A7: UC03 | B7: Pay by Credit Card | C7: Passenger | D7: Insert or tap a card, authorise the payment and receive the result. | E7: FR6, FR13, FR14 | F7: Yes | H7: 524H0041
A8: UC04 | B8: Pay by Bank QR Code | C8: Passenger | D8: Scan the dynamic VietQR code with a banking app and receive confirmation. | E8: FR7, FR13 | F8: Yes | H8: 524H0041
A9: UC05 | B9: Pay by Digital Wallet | C9: Passenger | D9: Choose a wallet, scan its QR code and receive confirmation. | E9: FR8, FR13 | F9: Yes | H9: 524H0041
A10: UC06 | B10: Print Ticket | C10: TVM (on behalf of Passenger) | D10: After confirmed payment, print the paper ticket with barcode and show the success screen. | E10: FR9, FR10 | F10: Yes | H10: 524H0041
A11: UC07 | B11: Cancel Transaction | C11: Passenger | D11: Cancel before payment is confirmed and return to Idle (extends UC01). | E11: FR11 | F11: Yes | H11: 524H0041
A12: UC08 | B12: Refund Failed Transaction | C12: Payment system (automatic) | D12: Refund or void a confirmed payment when no ticket was issued, or when payment arrives late. | E12: FR15, FR16 | F12: Yes | H12: 524H0041
A13: UC09 | B13: Service the TVM | C13: Maintenance Staff | D13: Sign in to the service menu, refill paper, run self-test and reset faults. | E13: FR21 | F13: Yes | H13: 524H0041
A14: UC10 | B14: Monitor TVM Status | C14: Operations Center Operator | D14: Receive heartbeats and alerts and see which TVMs or payment channels are unavailable. | E14: FR18, FR19 | F14: Yes | H14: 524H0041
A15: UC11 | B15: Manage Fares and Destinations | C15: Administrator | D15: Maintain destinations, ticket types and fares and distribute them to the TVMs. | E15: FR20 | F15: Yes | H15: 524H0041
A16: UC12 | B16: Reconcile Transactions | C16: Finance Officer | D16: Compare TVM transactions with provider settlement files and review mismatches. | E16: FR17, FR22 | F16: Yes | H16: 524H0041

Sheet Artifact Tracker
A1: Artifact Tracker
A2: Track every deliverable. Percent complete is calculated from the status.
A4: Task | B4: Artifact | C4: Marks | D4: Tool | E4: Owner (ID) | F4: File / link | G4: Status | H4: % complete | I4: Lecturer comment
A5: 1 | B5: Clarification Q&A (Excel) | C5: 5 | D5: Excel | E5: 524H0041 | F5: This workbook, Clarification Q&A sheet; report 2.1 | G5: Done | H5: =IF(G5="","",IF(G5="Done",1,IF(G5="In review",0.75,IF(G5="Draft",0.4,0)))) -> 1
A6: 2 | B6: Requirements Specification | C6: 15 | D6: Excel / Word | E6: 524H0041 | F6: This workbook, Requirements sheet; report 2.2 | G6: Done | H6: =IF(G6="","",IF(G6="Done",1,IF(G6="In review",0.75,IF(G6="Draft",0.4,0)))) -> 1
A7: 3 | B7: Use case diagram | C7: 5 | E7: 524H0041 | F7: Report 3.1.1 | G7: Done | H7: =IF(G7="","",IF(G7="Done",1,IF(G7="In review",0.75,IF(G7="Draft",0.4,0)))) -> 1
A8: 3 | B8: Use case descriptions | C8: 5 | E8: 524H0041 | F8: Report 3.1.3 | G8: Done | H8: =IF(G8="","",IF(G8="Done",1,IF(G8="In review",0.75,IF(G8="Draft",0.4,0)))) -> 1
A9: 4 | B9: Activity diagram: buy a ticket | C9: 5 | E9: 524H0074 | F9: Report 3.2.1 | G9: Done | H9: =IF(G9="","",IF(G9="Done",1,IF(G9="In review",0.75,IF(G9="Draft",0.4,0)))) -> 1
A10: 4 | B10: Activity diagram: payment gateways | C10: 5 | E10: 524H0074 | F10: Report 3.2.2 | G10: Done | H10: =IF(G10="","",IF(G10="Done",1,IF(G10="In review",0.75,IF(G10="Draft",0.4,0)))) -> 1
A11: 5 | B11: Sequence diagram | C11: 5 | E11: 524H0074 | F11: Report 3.3.1 | G11: Done | H11: =IF(G11="","",IF(G11="Done",1,IF(G11="In review",0.75,IF(G11="Draft",0.4,0)))) -> 1
A12: 5 | B12: State chart diagram | C12: 5 | E12: 524H0041 | F12: Report 3.3.2 | G12: Done | H12: =IF(G12="","",IF(G12="Done",1,IF(G12="In review",0.75,IF(G12="Draft",0.4,0)))) -> 1
A13: 5 | B13: Class diagram | C13: 5 | D13: Visual Studio | E13: 524H0158 | F13: Report 3.3.3 | G13: Done | H13: =IF(G13="","",IF(G13="Done",1,IF(G13="In review",0.75,IF(G13="Draft",0.4,0)))) -> 1
A14: 6 | B14: UI/UX wireframes or mockups | C14: 5 | D14: Figma | F14: https://www.figma.com/make/cpd1VhfymogiWUdNunS68w/Create-a-New-App?t=ycoktueirSDFqjfx-1 | G14: Done | H14: =IF(G14="","",IF(G14="Done",1,IF(G14="In review",0.75,IF(G14="Draft",0.4,0)))) -> 1
A15: 7 | B15: Architecture diagram | C15: 5 | E15: 524H0158 | F15: Report 4.2.1 | G15: Done | H15: =IF(G15="","",IF(G15="Done",1,IF(G15="In review",0.75,IF(G15="Draft",0.4,0)))) -> 1
A16: 7 | B16: Deployment diagram | C16: 5 | E16: 524H0158 | F16: Report 4.2.2 | G16: Done | H16: =IF(G16="","",IF(G16="Done",1,IF(G16="In review",0.75,IF(G16="Draft",0.4,0)))) -> 1
A17: 8 | B17: VS forward engineering (model to code) | C17: 4 | D17: Visual Studio | E17: 524H0074 | F17: Report 5.1.1 | G17: Done | H17: =IF(G17="","",IF(G17="Done",1,IF(G17="In review",0.75,IF(G17="Draft",0.4,0)))) -> 1
A18: 8 | B18: VS backward engineering (code to model) | C18: 3 | D18: Visual Studio | E18: 524H0074 | F18: Report 5.1.2 | G18: Done | H18: =IF(G18="","",IF(G18="Done",1,IF(G18="In review",0.75,IF(G18="Draft",0.4,0)))) -> 1
A19: 8 | B19: VS Code Map | C19: 3 | D19: Visual Studio | E19: 524H0074 | F19: Report 5.1.3 (picture generated by Gemini; VS Code Map not available) | G19: Draft | H19: =IF(G19="","",IF(G19="Done",1,IF(G19="In review",0.75,IF(G19="Draft",0.4,0)))) -> 0.4
A20: 9 | B20: GitHub repository with collaboration history | C20: 5 | D20: GitHub | F20: https://github.com/Narwhal1412/SE-QT2 | G20: Draft | H20: =IF(G20="","",IF(G20="Done",1,IF(G20="In review",0.75,IF(G20="Draft",0.4,0)))) -> 0.4
A21: 9 | B21: Copilot prompt documentation | C21: 5 | D21: GitHub Copilot | E21: 524H0074 | F21: Report 5.2.2; AI Prompt Log sheet | G21: Done | H21: =IF(G21="","",IF(G21="Done",1,IF(G21="In review",0.75,IF(G21="Draft",0.4,0)))) -> 1
A22: 10 | B22: Demo: C# and MSSQL input form | C22: 4 | D22: C# .NET 10 WinForms, MSSQL | E22: 524H0158 | F22: Report 5.3; TvmTicketing project in repository | G22: Done | H22: =IF(G22="","",IF(G22="Done",1,IF(G22="In review",0.75,IF(G22="Draft",0.4,0)))) -> 1
A23: 10 | B23: Demo: output report or success screen | C23: 3 | D23: C# .NET 10 WinForms | E23: 524H0158 | F23: Report 5.3 | G23: Done | H23: =IF(G23="","",IF(G23="Done",1,IF(G23="In review",0.75,IF(G23="Draft",0.4,0)))) -> 1
A24: 10 | B24: Demo: database script and run instructions | C24: 3 | D24: MSSQL | E24: 524H0158 | F24: TvmTicketing/Database/MetroGo_MSSQL_Setup.sql; Report 5.3 | G24: Done | H24: =IF(G24="","",IF(G24="Done",1,IF(G24="In review",0.75,IF(G24="Draft",0.4,0)))) -> 1
A25: – | B25: Report .docx | C25: 0 | D25: Word | F25: Report .docx | G25: Done | H25: =IF(G25="","",IF(G25="Done",1,IF(G25="In review",0.75,IF(G25="Draft",0.4,0)))) -> 1
A26: – | B26: readme.txt | C26: 0 | F26: Report Appendix A | G26: Done | H26: =IF(G26="","",IF(G26="Done",1,IF(G26="In review",0.75,IF(G26="Draft",0.4,0)))) -> 1
A27: – | B27: % contribution of each member | C27: 0 | F27: Report section 7 | G27: Done | H27: =IF(G27="","",IF(G27="Done",1,IF(G27="In review",0.75,IF(G27="Draft",0.4,0)))) -> 1
B29: Overall progress | C29: =IFERROR(AVERAGE(H5:H27),"") -> 0.94782609
B30: Artifacts done | C30: =COUNTIF(G5:G27,"Done")&" of 23" -> 21 of 23
A32: Marks column shows the weight of each task of the assignment (split across its artifacts for tracking only).

Sheet Consistency Check
A1: Model Consistency Check
A2: Diagrams must be syntactically correct, logically sound and aligned with each other.
A4: # | B4: Check | C4: Diagrams involved | D4: Student | E4: Lecturer | F4: Notes
A5: 1 | B5: Every use case in the diagram has a description, and every description is in the diagram | C5: Use case diagram / descriptions | D5: Yes | F5: Ticked in report section 3.4
A6: 2 | B6: Every step of the main flow appears in the activity diagram | C6: Descriptions / activity | D6: Yes | F6: Ticked in report section 3.4
A7: 3 | B7: Objects and messages in the sequence diagram exist as classes and methods in the class diagram | C7: Sequence / class | D7: Yes | F7: Ticked in report section 3.4
A8: 4 | B8: State names and transitions match the events in the sequence diagram | C8: State chart / sequence | D8: Yes | F8: Ticked in report section 3.4
A9: 5 | B9: Payment gateway steps match between both activity diagrams and the sequence diagram | C9: Activity / sequence | D9: Yes | F9: Ticked in report section 3.4
A10: 6 | B10: Requirement IDs are cited in the use cases | C10: Requirements / use cases | D10: Yes | F10: Ticked in report section 3.4
A11: 7 | B11: The class diagram matches the C# code from forward and backward engineering | C11: Class / code | D11: Yes | F11: Ticked in report section 3.4
A12: 8 | B12: The UI screens match the steps of the main flow | C12: Wireframes / descriptions
A13: 9 | B13: The architecture and deployment diagrams show the same components | C13: Architecture / deployment
A14: 10 | B14: UML notation is correct (arrows, multiplicities, guards, swim lanes) | C14: All diagrams

Sheet AI Prompt Log
A1: AI Prompt Log (Task 9)
A2: Document each prompt to GitHub Copilot (or a similar tool), how it helped, and how you validated the generated code.
A4: No. | B4: Date | C4: Student ID | D4: Tool | E4: Task / artifact | F4: Prompt used | G4: How the AI helped (boilerplate / logic / explanation) | H4: Output used? | I4: How we validated it (tests, code review, run) | J4: Lecturer comment
A5: 1 | C5: 524H0158 | D5: GitHub Copilot | E5: TicketController (C# controller) | F5: Implement C# TicketController with StartTransaction, CalculateFare, and CompleteSale methods coordinating printer and payment services | G5: Generated state-aware controller skeleton and transaction lifecycle methods | H5: Kept | I5: Verified against sequence diagram (3.3.1) and state transitions (3.3.2)
A6: 2 | C6: 524H0074 | D6: GitHub Copilot | E6: Code 128 barcode drawing (GDI+) | F6: Write a WinForms GDI+ method to draw Code 128 barcode bars dynamically using DrawRectangle given a string ticket number | G6: Generated procedural bar-and-gap drawing loop with modulo-based sizing | H6: Changed | I6: Tested barcode readability with scanner app and verified against ISO/IEC 15417 Change made: tuned bar width scaling and margins for kiosk card.
A7: 3 | C7: 524H0041 | D7: GitHub Copilot | E7: TransactionRepository (MSSQL MERGE, offline fallback) | F7: Generate T-SQL MERGE statements in TransactionRepository to upsert Transactions and Payments into MSSQL LocalDB with automatic in-memory fallback when offline. | G7: Produced parameterized SqlCommand MERGE queries and try-catch fallback logic for NFR4 offline buffering. | H7: Changed | I7: Tested both with (localdb)\MSSQLLocalDB running and with the SQL service stopped to verify NFR4 resilience. Change made: added SqlConnectionStringBuilder master DB check to auto-create MetroGoTVM if missing.
A8: 4 | C8: 524H0158 | D8: GitHub Copilot | E8: WinForms custom controls (RoundedCardPanel, MetroButton) | F8: Create a custom WinForms RoundedCardPanel and MetroButton using GraphicsPath anti-aliased arcs to match the Figma light-slate kiosk theme. | G8: Generated reusable GDI+ rounded-rectangle path helpers and hover state overrides. | H8: Kept | I8: Compared rendered WinForms screens side-by-side against Figma frames S01–S07 to ensure pixel-accuracy.
A9: 5 | C9: 524H0074 | D9: GitHub Copilot | E9: Refund on print failure (UC08) | F9: Implement PaymentService.RequestRefund and TicketController.HandlePrintFailure to trigger automatic refund when TicketPrinter.Status is Jammed or PaperOut. | G9: Created the error-handling branch in CompleteSale() that marks the transaction RefundPending and logs a refund reference. | H9: Kept | I9: Triggered "Simulate Print Jam (UC08)" in the demo app and verified the refund entry in the Daily Reconciliation tab.
A10: 6 | C10: 524H0041 | D10: GitHub Copilot | E10: QR matrix renderer (GDI+) | F10: Write a procedural QR matrix renderer in GDI+ with three 7x7 finder patterns and deterministic hash modules seeded by the transaction code. | G10: Provided the DrawFinder helper and deterministic grid loop for VietQR and wallet QR previews. | H10: Changed | I10: Verified that switching between MoMo, ZaloPay, VNPay, and VietQR generates distinct QR matrices per transaction ID. Change made: adjusted module sizing to fit the 220x232 payment card.
A11: 7
A12: 8
A13: 9
A14: 10
A15: 11
A16: 12
A17: 13
A18: 14
A19: 15
A20: 16
A21: 17
A22: 18
... A44: 40
E46: Kept | F46: =COUNTIF(H5:H44,"Kept") -> 3
E47: Changed | F47: =COUNTIF(H5:H44,"Changed") -> 3
E48: Rejected | F48: =COUNTIF(H5:H44,"Rejected") -> 0
E49: Used without validation | F49: =COUNTIFS(H5:H44,"<>",I5:I44,"") -> 0
A51: Every AI output you keep or change must have a validation. The red counter shows prompts with a decision but no validation.

Sheet Commit Log
A1: Commit and Pull Request Log
A2: Record the evidence of collaboration each week. Use the Student ID exactly as in the Team sheet.
A4: Week | B4: Date | C4: Student ID | D4: Branch | E4: Commits | F4: Pull requests | G4: What was done / link | H4: Lecturer comment

Sheet Progress Log
A1: Weekly Progress Log
A2: Fill in at the end of each lab week. Adjust the planned work to your own schedule.
A4: Checkpoint | B4: Planned for this week | C4: What we actually did | D4: Evidence (commit / PR / screenshot link) | E4: Blockers and help needed | F4: Status (team) | G4: Lecturer feedback | H4: Checkpoint
A5: Week 1 | B5: Read the assignment, form the team, set up GitHub, start Clarification Q&A
A6: Week 2 | B6: Requirements specification (FR, NFR with metrics, domain)
A7: Week 3 | B7: Use case model and activity diagrams
A8: Week 4 | B8: Sequence, state chart, class diagram; wireframes; architecture
A9: Week 5 | B9: Forward and backward engineering, Code Map; demo application
A10: Week 6 | B10: Finish demo, report, readme.txt, self-marking
A12: Checkpoints met | B12: =COUNTIF(H5:H10,"Met")&" of 6" -> 0 of 6
A14: Update this sheet at the end of every lab week. A short, honest record earns the process mark; a blank log does not.

Sheet Marking
A1: Marking: Self and Lecturer
A2: Enter marks out of each task's Max. Yellow = student self-mark, green = lecturer mark.
A4: No. | B4: Task | C4: Max (marks) | D4: What to check for full marks | E4: Student self-mark | F4: Lecturer mark | G4: Difference (self − lecturer) | H4: Student justification / evidence | I4: Lecturer comments
A5: 1 | B5: Clarification Q&A (Excel) | C5: 5 | D5: Thorough questions uncovering hidden complexity, each with a logical assumed answer and a requirement link. | G5: =IF(AND(ISNUMBER(E5),ISNUMBER(F5)),E5-F5,"")
A6: 2 | B6: Requirements Specification | C6: 15 | D6: Functional, non-functional and domain requirements with IDs. Strict, measurable reliability and response-time limits. | G6: =IF(AND(ISNUMBER(E6),ISNUMBER(F6)),E6-F6,"")
A7: 3 | B7: Use Case Modeling | C7: 10 | D7: Correct use case diagram and a detailed description for every use case. | G7: =IF(AND(ISNUMBER(E7),ISNUMBER(F7)),E7-F7,"")
A8: 4 | B8: Activity Diagrams | C8: 10 | D8: Buy-a-ticket flow with failures, and a separate payment gateway integration diagram. | G8: =IF(AND(ISNUMBER(E8),ISNUMBER(F8)),E8-F8,"")
A9: 5 | B9: Detailed System Modeling: Buy a Ticket | C9: 15 | D9: Sequence, state chart and class diagram: correct, logical and aligned with each other. | G9: =IF(AND(ISNUMBER(E9),ISNUMBER(F9)),E9-F9,"")
A10: 6 | B10: UI/UX Design | C10: 5 | D10: Modern, intuitive wireframes or mockups for the TVM screens. | G10: =IF(AND(ISNUMBER(E10),ISNUMBER(F10)),E10-F10,"")
A11: 7 | B11: Architectural Design | C11: 10 | D11: Logical, modular architecture (MVC or system-in-a-box) suited to the hardware; deployment diagram with API context. | G11: =IF(AND(ISNUMBER(E11),ISNUMBER(F11)),E11-F11,"")
A12: 8 | B12: Visual Studio Engineering | C12: 10 | D12: Forward engineering, backward engineering and a Code Map, all shown and explained. | G12: =IF(AND(ISNUMBER(E12),ISNUMBER(F12)),E12-F12,"")
A13: 9 | B13: GitHub & AI Tooling (Copilot) | C13: 10 | D13: Rich commit history from all members; Copilot prompts documented with validation of the output. | G13: =IF(AND(ISNUMBER(E13),ISNUMBER(F13)),E13-F13,"")
A14: 10 | B14: Demo Application (C# and MSSQL) | C14: 10 | D14: Runs smoothly: input form and output report or success screen for the ticket buying flow. | G14: =IF(AND(ISNUMBER(E14),ISNUMBER(F14)),E14-F14,"")
B15: Total (/100) | C15: =SUM(C5:C14) -> 100 | E15: =SUM(E5:E14) -> 0 | F15: =SUM(F5:F14) -> 0 | G15: =E15-F15 -> 0
A17: A red difference means self-mark and lecturer mark differ by more than 20% of the task's Max: discuss it in the feedback session.

Sheet Summary
A1: Group Summary and Results
A2: Results are calculated from the Marking sheet.
A4: Group name | B4: =IF(Team!B4="","",Team!B4) -> Group 69
A5: Weight of this assignment in QT2 | B5: 0.2
A6: Marked by / date
A8: Group results
A9: Measure | B9: Student self-marking | C9: Lecturer | D9: Difference
A10: Total (/100) | B10: =Marking!E15 -> 0 | C10: =Marking!F15 -> 0 | D10: =B10-C10 -> 0
A11: Contribution to QT2 (points) | B11: =B10*$B$5 -> 0 | C11: =C10*$B$5 -> 0 | D11: =B11-C11 -> 0
A12: Bonus point toward the Final Project (lecturer, 0 or 1)
A14: Individual marks
A15: Member | B15: Student ID | C15: % contribution | D15: Lecturer adjustment factor (0.70-1.00, blank = 1) | E15: Individual mark (/100) | F15: Individual QT2 points
A16: =IF(Team!B11="","",Team!B11) -> Trần Đỗ Quốc Anh | B16: =IF(Team!C11="","",Team!C11) -> 524H0041 | C16: =IF(Team!C11="","",Team!E11) -> 0.3 | E16: =IF($B16="","",ROUND($C$10*IF($D16="",1,$D16),2)) -> 0 | F16: =IF($B16="","",ROUND(E16*$B$5,2)) -> 0
A17: =IF(Team!B12="","",Team!B12) -> Nguyễn Gia Huy | B17: =IF(Team!C12="","",Team!C12) -> 524H0158 | C17: =IF(Team!C12="","",Team!E12) -> 0.4 | E17: =IF($B17="","",ROUND($C$10*IF($D17="",1,$D17),2)) -> 0 | F17: =IF($B17="","",ROUND(E17*$B$5,2)) -> 0
A18: =IF(Team!B13="","",Team!B13) -> Lê Anh Tuân | B18: =IF(Team!C13="","",Team!C13) -> 524H0074 | C18: =IF(Team!C13="","",Team!E13) -> 0.3 | E18: =IF($B18="","",ROUND($C$10*IF($D18="",1,$D18),2)) -> 0 | F18: =IF($B18="","",ROUND(E18*$B$5,2)) -> 0
A19: =IF(Team!B14="","",Team!B14) | B19: =IF(Team!C14="","",Team!C14) | C19: =IF(Team!C14="","",Team!E14) | E19: =IF($B19="","",ROUND($C$10*IF($D19="",1,$D19),2)) | F19: =IF($B19="","",ROUND(E19*$B$5,2))
A20: =IF(Team!B15="","",Team!B15) | B20: =IF(Team!C15="","",Team!C15) | C20: =IF(Team!C15="","",Team!E15) | E20: =IF($B20="","",ROUND($C$10*IF($D20="",1,$D20),2)) | F20: =IF($B20="","",ROUND(E20*$B$5,2))
A22: The factor is reduced below 1.00 only when the evidence (Git history, pull requests, progress log, individual questions) shows a clearly smaller contribution.
A24: Comments
A25: Student reflection (optional)
A26: Lecturer feedback
